Traceback (most recent call last):
  File "/usr/share/miniconda/envs/ml-latest/lib/python3.9/site-packages/jupyter_cache/executors/utils.py", line 51, in single_nb_execution
    executenb(
  File "/usr/share/miniconda/envs/ml-latest/lib/python3.9/site-packages/nbclient/client.py", line 1117, in execute
    return NotebookClient(nb=nb, resources=resources, km=km, **kwargs).execute()
  File "/usr/share/miniconda/envs/ml-latest/lib/python3.9/site-packages/nbclient/util.py", line 78, in wrapped
    return just_run(coro(*args, **kwargs))
  File "/usr/share/miniconda/envs/ml-latest/lib/python3.9/site-packages/nbclient/util.py", line 57, in just_run
    return loop.run_until_complete(coro)
  File "/usr/share/miniconda/envs/ml-latest/lib/python3.9/asyncio/base_events.py", line 642, in run_until_complete
    return future.result()
  File "/usr/share/miniconda/envs/ml-latest/lib/python3.9/site-packages/nbclient/client.py", line 558, in async_execute
    await self.async_execute_cell(
  File "/usr/share/miniconda/envs/ml-latest/lib/python3.9/site-packages/nbclient/client.py", line 862, in async_execute_cell
    self._check_raise_for_error(cell, exec_reply)
  File "/usr/share/miniconda/envs/ml-latest/lib/python3.9/site-packages/nbclient/client.py", line 765, in _check_raise_for_error
    raise CellExecutionError.from_cell_and_msg(cell, exec_reply_content)
nbclient.exceptions.CellExecutionError: An error occurred while executing the following cell:
------------------
labels = tree.arrays(branches=['label_QCD_b', 
                               'label_QCD_bb', 
                               'label_QCD_c', 
                               'label_QCD_cc', 
                               'label_QCD_others', 
                               'label_H_bb', 
                               'sample_isQCD'], 
                     entrystop=20000,
                     namedecode='utf-8')
------------------

[0;31m---------------------------------------------------------------------------[0m
[0;31mTypeError[0m                                 Traceback (most recent call last)
[0;32m/tmp/ipykernel_3621/2505705034.py[0m in [0;36m<module>[0;34m[0m
[0;32m----> 1[0;31m labels = tree.arrays(branches=['label_QCD_b', 
[0m[1;32m      2[0m                                [0;34m'label_QCD_bb'[0m[0;34m,[0m[0;34m[0m[0;34m[0m[0m
[1;32m      3[0m                                [0;34m'label_QCD_c'[0m[0;34m,[0m[0;34m[0m[0;34m[0m[0m
[1;32m      4[0m                                [0;34m'label_QCD_cc'[0m[0;34m,[0m[0;34m[0m[0;34m[0m[0m
[1;32m      5[0m                                [0;34m'label_QCD_others'[0m[0;34m,[0m[0;34m[0m[0;34m[0m[0m

[0;31mTypeError[0m: arrays() got an unexpected keyword argument 'branches'
TypeError: arrays() got an unexpected keyword argument 'branches'

