Traceback (most recent call last):
  File "/usr/share/miniconda/envs/ml-latest/lib/python3.9/site-packages/jupyter_cache/executors/utils.py", line 51, in single_nb_execution
    executenb(
  File "/usr/share/miniconda/envs/ml-latest/lib/python3.9/site-packages/nbclient/client.py", line 1117, in execute
    return NotebookClient(nb=nb, resources=resources, km=km, **kwargs).execute()
  File "/usr/share/miniconda/envs/ml-latest/lib/python3.9/site-packages/nbclient/util.py", line 78, in wrapped
    return just_run(coro(*args, **kwargs))
  File "/usr/share/miniconda/envs/ml-latest/lib/python3.9/site-packages/nbclient/util.py", line 57, in just_run
    return loop.run_until_complete(coro)
  File "/usr/share/miniconda/envs/ml-latest/lib/python3.9/asyncio/base_events.py", line 642, in run_until_complete
    return future.result()
  File "/usr/share/miniconda/envs/ml-latest/lib/python3.9/site-packages/nbclient/client.py", line 558, in async_execute
    await self.async_execute_cell(
  File "/usr/share/miniconda/envs/ml-latest/lib/python3.9/site-packages/nbclient/client.py", line 862, in async_execute_cell
    self._check_raise_for_error(cell, exec_reply)
  File "/usr/share/miniconda/envs/ml-latest/lib/python3.9/site-packages/nbclient/client.py", line 765, in _check_raise_for_error
    raise CellExecutionError.from_cell_and_msg(cell, exec_reply_content)
nbclient.exceptions.CellExecutionError: An error occurred while executing the following cell:
------------------
# load training file
feature_array, label_array, spec_array = utils.get_features_labels('root://eospublic.cern.ch//eos/opendata/cms/datascience/HiggsToBBNtupleProducerTool/HiggsToBBNTuple_HiggsToBB_QCD_RunII_13TeV_MC/train/ntuple_merged_10.root', 
                                                                   features, spectators, labels,
                                                             remove_mass_pt_window=False,
                                                             entrystop=20000)
------------------

[0;31m---------------------------------------------------------------------------[0m
[0;31mTypeError[0m                                 Traceback (most recent call last)
[0;32m/tmp/ipykernel_3648/60281719.py[0m in [0;36m<module>[0;34m[0m
[1;32m      1[0m [0;31m# load training file[0m[0;34m[0m[0;34m[0m[0m
[0;32m----> 2[0;31m feature_array, label_array, spec_array = utils.get_features_labels('root://eospublic.cern.ch//eos/opendata/cms/datascience/HiggsToBBNtupleProducerTool/HiggsToBBNTuple_HiggsToBB_QCD_RunII_13TeV_MC/train/ntuple_merged_10.root', 
[0m[1;32m      3[0m                                                                    [0mfeatures[0m[0;34m,[0m [0mspectators[0m[0;34m,[0m [0mlabels[0m[0;34m,[0m[0;34m[0m[0;34m[0m[0m
[1;32m      4[0m                                                              [0mremove_mass_pt_window[0m[0;34m=[0m[0;32mFalse[0m[0;34m,[0m[0;34m[0m[0;34m[0m[0m
[1;32m      5[0m                                                              entrystop=20000)

[0;32m~/work/capstone-particle-physics-domain/capstone-particle-physics-domain/weeks/utils.py[0m in [0;36mget_features_labels[0;34m(file_name, features, spectators, labels, remove_mass_pt_window, entrystop)[0m
[1;32m      6[0m     [0mroot_file[0m [0;34m=[0m [0muproot[0m[0;34m.[0m[0mopen[0m[0;34m([0m[0mfile_name[0m[0;34m)[0m[0;34m[0m[0;34m[0m[0m
[1;32m      7[0m     [0mtree[0m [0;34m=[0m [0mroot_file[0m[0;34m[[0m[0;34m'deepntuplizer/tree'[0m[0;34m][0m[0;34m[0m[0;34m[0m[0m
[0;32m----> 8[0;31m     feature_array = tree.arrays(branches=features, 
[0m[1;32m      9[0m                                 [0mentrystop[0m[0;34m=[0m[0mentrystop[0m[0;34m,[0m[0;34m[0m[0;34m[0m[0m
[1;32m     10[0m                                 namedecode='utf-8')

[0;31mTypeError[0m: arrays() got an unexpected keyword argument 'branches'
TypeError: arrays() got an unexpected keyword argument 'branches'

