Traceback (most recent call last):
  File "/usr/share/miniconda/envs/ml-latest/lib/python3.9/site-packages/jupyter_cache/executors/utils.py", line 51, in single_nb_execution
    executenb(
  File "/usr/share/miniconda/envs/ml-latest/lib/python3.9/site-packages/nbclient/client.py", line 1117, in execute
    return NotebookClient(nb=nb, resources=resources, km=km, **kwargs).execute()
  File "/usr/share/miniconda/envs/ml-latest/lib/python3.9/site-packages/nbclient/util.py", line 78, in wrapped
    return just_run(coro(*args, **kwargs))
  File "/usr/share/miniconda/envs/ml-latest/lib/python3.9/site-packages/nbclient/util.py", line 57, in just_run
    return loop.run_until_complete(coro)
  File "/usr/share/miniconda/envs/ml-latest/lib/python3.9/asyncio/base_events.py", line 642, in run_until_complete
    return future.result()
  File "/usr/share/miniconda/envs/ml-latest/lib/python3.9/site-packages/nbclient/client.py", line 558, in async_execute
    await self.async_execute_cell(
  File "/usr/share/miniconda/envs/ml-latest/lib/python3.9/site-packages/nbclient/client.py", line 862, in async_execute_cell
    self._check_raise_for_error(cell, exec_reply)
  File "/usr/share/miniconda/envs/ml-latest/lib/python3.9/site-packages/nbclient/client.py", line 765, in _check_raise_for_error
    raise CellExecutionError.from_cell_and_msg(cell, exec_reply_content)
nbclient.exceptions.CellExecutionError: An error occurred while executing the following cell:
------------------
# load testing file
feature_array_test, label_array_test, spec_array_test = utils.get_features_labels('root://eospublic.cern.ch//eos/opendata/cms/datascience/HiggsToBBNtupleProducerTool/HiggsToBBNTuple_HiggsToBB_QCD_RunII_13TeV_MC/test/ntuple_merged_0.root',
                                                                                  features, spectators, labels,
                                                                                  remove_mass_pt_window=False)
                      
# make image
X_test = utils.make_image(feature_array_test)
------------------

[0;31m---------------------------------------------------------------------------[0m
[0;31mMemoryError[0m                               Traceback (most recent call last)
[0;32m/tmp/ipykernel_4399/4121787654.py[0m in [0;36m<module>[0;34m[0m
[1;32m      5[0m [0;34m[0m[0m
[1;32m      6[0m [0;31m# make image[0m[0;34m[0m[0;34m[0m[0m
[0;32m----> 7[0;31m [0mX_test[0m [0;34m=[0m [0mutils[0m[0;34m.[0m[0mmake_image[0m[0;34m([0m[0mfeature_array_test[0m[0;34m)[0m[0;34m[0m[0;34m[0m[0m
[0m
[0;32m~/work/capstone-particle-physics-domain/capstone-particle-physics-domain/weeks/utils.py[0m in [0;36mmake_image[0;34m(feature_array, n_pixels, img_ranges)[0m
[1;32m     58[0m     [0mx[0m [0;34m=[0m [0mfeature_array[0m[0;34m[[0m[0;34m:[0m[0;34m,[0m [0;36m1[0m[0;34m][0m  [0;31m# etarel[0m[0;34m[0m[0;34m[0m[0m
[1;32m     59[0m     [0my[0m [0;34m=[0m [0mfeature_array[0m[0;34m[[0m[0;34m:[0m[0;34m,[0m [0;36m2[0m[0;34m][0m  [0;31m# phirel[0m[0;34m[0m[0;34m[0m[0m
[0;32m---> 60[0;31m     [0mimg[0m [0;34m=[0m [0mnp[0m[0;34m.[0m[0mzeros[0m[0;34m([0m[0mshape[0m[0;34m=[0m[0;34m([0m[0mlen[0m[0;34m([0m[0mwgt[0m[0;34m)[0m[0;34m,[0m [0mn_pixels[0m[0;34m,[0m [0mn_pixels[0m[0;34m)[0m[0;34m)[0m[0;34m[0m[0;34m[0m[0m
[0m[1;32m     61[0m     [0;32mfor[0m [0mi[0m [0;32min[0m [0mrange[0m[0;34m([0m[0mlen[0m[0;34m([0m[0mwgt[0m[0;34m)[0m[0;34m)[0m[0;34m:[0m[0;34m[0m[0;34m[0m[0m
[1;32m     62[0m         hist2d, xedges, yedges = np.histogram2d(x[i], y[i],

[0;31mMemoryError[0m: Unable to allocate 70.3 GiB for an array with shape (188007, 224, 224) and data type float64
MemoryError: Unable to allocate 70.3 GiB for an array with shape (188007, 224, 224) and data type float64

