Traceback (most recent call last):
  File "/usr/share/miniconda/envs/ml-latest/lib/python3.7/site-packages/jupyter_cache/executors/utils.py", line 56, in single_nb_execution
    record_timing=False,
  File "/usr/share/miniconda/envs/ml-latest/lib/python3.7/site-packages/nbclient/client.py", line 1087, in execute
    return NotebookClient(nb=nb, resources=resources, km=km, **kwargs).execute()
  File "/usr/share/miniconda/envs/ml-latest/lib/python3.7/site-packages/nbclient/util.py", line 74, in wrapped
    return just_run(coro(*args, **kwargs))
  File "/usr/share/miniconda/envs/ml-latest/lib/python3.7/site-packages/nbclient/util.py", line 53, in just_run
    return loop.run_until_complete(coro)
  File "/usr/share/miniconda/envs/ml-latest/lib/python3.7/asyncio/base_events.py", line 587, in run_until_complete
    return future.result()
  File "/usr/share/miniconda/envs/ml-latest/lib/python3.7/site-packages/nbclient/client.py", line 541, in async_execute
    cell, index, execution_count=self.code_cells_executed + 1
  File "/usr/share/miniconda/envs/ml-latest/lib/python3.7/site-packages/nbclient/client.py", line 832, in async_execute_cell
    self._check_raise_for_error(cell, exec_reply)
  File "/usr/share/miniconda/envs/ml-latest/lib/python3.7/site-packages/nbclient/client.py", line 740, in _check_raise_for_error
    raise CellExecutionError.from_cell_and_msg(cell, exec_reply['content'])
nbclient.exceptions.CellExecutionError: An error occurred while executing the following cell:
------------------
# run model inference on test data set
predict_array_adv = []
label_array_test = []
spec_array_test = []

for t in tqdm(test_generator,total=len(test_generator)):
    label_array_test.append(t[1][0])
    spec_array_test.append(t[1][1])
    predict_array_adv.append(keras_model_adv.predict(t[0])[0])
predict_array_adv = np.concatenate(predict_array_adv,axis=0)
label_array_test = np.concatenate(label_array_test,axis=0)
spec_array_test = np.concatenate(spec_array_test,axis=0)
------------------

[0;31m---------------------------------------------------------------------------[0m
[0;31mValueError[0m                                Traceback (most recent call last)
[0;32m<ipython-input-8-8e212cefe775>[0m in [0;36m<module>[0;34m[0m
[1;32m      8[0m     [0mspec_array_test[0m[0;34m.[0m[0mappend[0m[0;34m([0m[0mt[0m[0;34m[[0m[0;36m1[0m[0;34m][0m[0;34m[[0m[0;36m1[0m[0;34m][0m[0;34m)[0m[0;34m[0m[0;34m[0m[0m
[1;32m      9[0m     [0mpredict_array_adv[0m[0;34m.[0m[0mappend[0m[0;34m([0m[0mkeras_model_adv[0m[0;34m.[0m[0mpredict[0m[0;34m([0m[0mt[0m[0;34m[[0m[0;36m0[0m[0;34m][0m[0;34m)[0m[0;34m[[0m[0;36m0[0m[0;34m][0m[0;34m)[0m[0;34m[0m[0;34m[0m[0m
[0;32m---> 10[0;31m [0mpredict_array_adv[0m [0;34m=[0m [0mnp[0m[0;34m.[0m[0mconcatenate[0m[0;34m([0m[0mpredict_array_adv[0m[0;34m,[0m[0maxis[0m[0;34m=[0m[0;36m0[0m[0;34m)[0m[0;34m[0m[0;34m[0m[0m
[0m[1;32m     11[0m [0mlabel_array_test[0m [0;34m=[0m [0mnp[0m[0;34m.[0m[0mconcatenate[0m[0;34m([0m[0mlabel_array_test[0m[0;34m,[0m[0maxis[0m[0;34m=[0m[0;36m0[0m[0;34m)[0m[0;34m[0m[0;34m[0m[0m
[1;32m     12[0m [0mspec_array_test[0m [0;34m=[0m [0mnp[0m[0;34m.[0m[0mconcatenate[0m[0;34m([0m[0mspec_array_test[0m[0;34m,[0m[0maxis[0m[0;34m=[0m[0;36m0[0m[0;34m)[0m[0;34m[0m[0;34m[0m[0m

[0;32m<__array_function__ internals>[0m in [0;36mconcatenate[0;34m(*args, **kwargs)[0m

[0;31mValueError[0m: need at least one array to concatenate
ValueError: need at least one array to concatenate

